Workbook

Sheet general
A1: No | B1: type | C1: name | D1: 限制类型 | E1: 限制次数 | F1: condition_description | G1: cost_description | H1: effect_description | I1: condition_name | J1: condition_value | K1: cost_condition_name | L1: cost_condition_value | M1: cost_name | N1: cost_value | O1: effect_name | P1: effect_value | Q1: 是否buff | R1: 主被动 | S1: 发动类型 | T1: 进入连锁（此项暂不可用） | U1: 触发限制类型 | V1: 是否token | W1: 初始量 | X1: 添置类型（独立、叠加、覆盖） | Y1: 持续时间单位 | Z1: 持续时长
A2: 400 | B2: 隐藏效果 | C2: 连攻 | F2: =IF(I2="","",SUBSTITUTE(VLOOKUP(I2,event!E:F,2,0),"?",J2)) -> 自己普攻成功或自己回合自己未处于搏斗状态 | G2: =IF(M2="","",SUBSTITUTE(VLOOKUP(M2,effect!B:E,4,0),"?",N2)) | H2: =SUBSTITUTE(VLOOKUP(O2,effect!B:E,4,0),"?",P2) -> 自己发动1次普攻 | I2: i_success_attack_or_my_turn_positive | O2: Effect_i_claim_attack
A3: 401 | B3: 隐藏效果 | C3: 闪 | F3: =IF(I3="","",SUBSTITUTE(VLOOKUP(I3,event!E:F,2,0),"?",J3)) -> 自己即将受到普攻 | G3: =IF(M3="","",SUBSTITUTE(VLOOKUP(M3,effect!B:E,4,0),"?",N3)) | H3: =SUBSTITUTE(VLOOKUP(O3,effect!B:E,4,0),"?",P3) -> 自己躲避本次普攻 | I3: i_will_be_attacked | O3: Effect_i_escape_attack
A4: 402 | B4: 隐藏效果 | C4: +4血 | F4: =IF(I4="","",SUBSTITUTE(VLOOKUP(I4,event!E:F,2,0),"?",J4)) | G4: =IF(M4="","",SUBSTITUTE(VLOOKUP(M4,effect!B:E,4,0),"?",N4)) | H4: =SUBSTITUTE(VLOOKUP(O4,effect!B:E,4,0),"?",P4) -> 自己指定1人回复4血 | O4: Effect_i_point_one_get_heal | P4: 4
A5: 403 | B5: 隐藏效果 | C5: 暗枪 | F5: =IF(I5="","",SUBSTITUTE(VLOOKUP(I5,event!E:F,2,0),"?",J5)) -> 自己参与搏斗 | G5: =IF(M5="","",SUBSTITUTE(VLOOKUP(M5,effect!B:E,4,0),"?",N5)) | H5: =SUBSTITUTE(VLOOKUP(O5,effect!B:E,4,0),"?",P5) -> 自己使 目标 伤1血 | I5: i_success_do_fight | O5: Effect_i_let_enemy_effect_dmg | P5: 1
A6: 404 | B6: 隐藏效果 | C6: 稻草人 | F6: =IF(I6="","",SUBSTITUTE(VLOOKUP(I6,event!E:F,2,0),"?",J6)) -> 自己即将受到普攻 | G6: =IF(M6="","",SUBSTITUTE(VLOOKUP(M6,effect!B:E,4,0),"?",N6)) | H6: =SUBSTITUTE(VLOOKUP(O6,effect!B:E,4,0),"?",P6) -> 躲避此次普攻，目标 武器全被破坏 | I6: i_will_be_attacked | O6: Effect_SP_scarecrow
A7: 405 | B7: 隐藏效果 | C7: 憎恨 | F7: =IF(I7="","",SUBSTITUTE(VLOOKUP(I7,event!E:F,2,0),"?",J7)) | G7: =IF(M7="","",SUBSTITUTE(VLOOKUP(M7,effect!B:E,4,0),"?",N7)) | H7: =SUBSTITUTE(VLOOKUP(O7,effect!B:E,4,0),"?",P7) -> 自己选一以下效果进行发动： (1)指定1人的人物效果一轮回内无法发动 (2)破坏场上一张 装备卡 或 场景卡 或 结界卡 (3)非人物卡 发动无效并破坏 | O7: Effect_hatred
A8: 14050 | B8: 减益效果 | C8: 憎恨1 | H8: =SUBSTITUTE(VLOOKUP(O8,effect!B:E,4,0),"?",P8) -> 自己自身效果无效化 | O8: Buff_myself_silent | Q8: 是 | R8: 被动 | Y8: 回合 | Z8: 1
A9: 406 | B9: 隐藏效果 | C9: 极天束 | F9: =IF(I9="","",SUBSTITUTE(VLOOKUP(I9,event!E:F,2,0),"?",J9)) -> 自己普攻成功 | G9: =IF(M9="","",SUBSTITUTE(VLOOKUP(M9,effect!B:E,4,0),"?",N9)) | H9: =SUBSTITUTE(VLOOKUP(O9,effect!B:E,4,0),"?",P9) -> 自己使 目标 伤2血 | I9: i_success_attack | O9: Effect_i_let_enemy_effect_dmg | P9: 2
A10: 407 | B10: 隐藏效果 | C10: 蓝爆冰晶 | F10: =IF(I10="","",SUBSTITUTE(VLOOKUP(I10,event!E:F,2,0),"?",J10)) -> 己方回合自己未处于搏斗 | G10: =IF(M10="","",SUBSTITUTE(VLOOKUP(M10,effect!B:E,4,0),"?",N10)) | H10: =SUBSTITUTE(VLOOKUP(O10,effect!B:E,4,0),"?",P10) -> 自己指定1人3次50%伤1血，若全中则其装备全部被破坏 | I10: STATE_team_turn_i_positive | O10: compound_ice_burst
A11: 14070 | B11: 减益效果 | C11: 蓝爆冰晶1 | F11: =IF(I11="","",SUBSTITUTE(VLOOKUP(I11,event!E:F,2,0),"?",J11)) -> 自己受到伤血效果 | H11: =SUBSTITUTE(VLOOKUP(O11,effect!B:E,4,0),"?",P11) -> 给本buff增加token数量，检测token数量若超过三，摧毁自己所有武器 | I11: i_be_dmg_effect | O11: Effect_SP_ice_burst | Q11: 是 | U11: 连锁层 | V11: 是 | W11: 0 | Y11: 此次效果伤血 | Z11: 3
A12: 60 | B12: 效果卡 | C12: 神起·焰射 | F12: =IF(I12="","",SUBSTITUTE(VLOOKUP(I12,event!E:F,2,0),"?",J12)) -> 自己普攻失败 | G12: =IF(M12="","",SUBSTITUTE(VLOOKUP(M12,effect!B:E,4,0),"?",N12)) -> 自己丢光手卡 | H12: =SUBSTITUTE(VLOOKUP(O12,effect!B:E,4,0),"?",P12) -> 敌方所有人武器全部破坏且伤1血 | I12: i_failed_attack | M12: Effect_i_discard_card_all | O12: Effect_SP_fire_splash | P12: 1
A13: 61 | B13: 效果卡 | C13: 近击·搏杀 | F13: =IF(I13="","",SUBSTITUTE(VLOOKUP(I13,event!E:F,2,0),"?",J13)) -> 自己参与的1次事件连锁超过4次 | G13: =IF(M13="","",SUBSTITUTE(VLOOKUP(M13,effect!B:E,4,0),"?",N13)) | H13: =SUBSTITUTE(VLOOKUP(O13,effect!B:E,4,0),"?",P13) -> 自己对 目标 造成3血超伤，此回合被强制结束 | I13: STATE_i_involve_event_over_4_chains | O13: Effect_SP_burst_fight | P13: 3
A14: 62 | B14: 效果卡 | C14: 阴势·突进 | F14: =IF(I14="","",SUBSTITUTE(VLOOKUP(I14,event!E:F,2,0),"?",J14)) -> 自己回合自己未处于搏斗 | G14: =IF(M14="","",SUBSTITUTE(VLOOKUP(M14,effect!B:E,4,0),"?",N14)) | H14: =SUBSTITUTE(VLOOKUP(O14,effect!B:E,4,0),"?",P14) -> 自己指定1人伤1血且此回合不能行动(对手可丢1卡躲避此效果) | I14: STATE_my_turn_positive | O14: compound_dark_rush
A15: 10620 | B15: 增益效果 | C15: 阴势·突进1 | F15: =IF(I15="","",SUBSTITUTE(VLOOKUP(I15,event!E:F,2,0),"?",J15)) -> 自己成功造成效果伤血 | G15: =IF(M15="","",SUBSTITUTE(VLOOKUP(M15,effect!B:E,4,0),"?",N15)) | H15: =SUBSTITUTE(VLOOKUP(O15,effect!B:E,4,0),"?",P15) -> 给单一对手添加buff | I15: i_success_do_dmg_effect | O15: Effect_get_buff_one_enemy | P15: =A16 -> 10621 | Q15: 是 | R15: 被动 | S15: 必发 | U15: 连锁层 | X15: 独立 | Y15: 此次效果伤血
A16: 10621 | B16: 减益效果 | C16: 阴势·突进2 | F16: =IF(I16="","",SUBSTITUTE(VLOOKUP(I16,event!E:F,2,0),"?",J16)) | G16: =IF(M16="","",SUBSTITUTE(VLOOKUP(M16,effect!B:E,4,0),"?",N16)) | H16: =SUBSTITUTE(VLOOKUP(O16,effect!B:E,4,0),"?",P16) -> 自己无法行动 | O16: Buff_unmovable | Q16: 是 | R16: 被动 | X16: 独立 | Y16: 回合 | Z16: 1
A17: 63 | B17: 效果卡 | C17: 神空·闪降 | F17: =IF(I17="","",SUBSTITUTE(VLOOKUP(I17,event!E:F,2,0),"?",J17)) -> 自己回合自己未处于搏斗 | G17: =IF(M17="","",SUBSTITUTE(VLOOKUP(M17,effect!B:E,4,0),"?",N17)) | H17: =SUBSTITUTE(VLOOKUP(O17,effect!B:E,4,0),"?",P17) -> 自己抽1卡,将抽到的该卡公开,自己这回合的规则性普攻次数被重置为1 | I17: STATE_my_turn_positive | O17: compound_skyfall_dazzling_entrance
A18: 10630 | B18: 减益效果 | C18: 神空·闪降1 | F18: =IF(I18="","",SUBSTITUTE(VLOOKUP(I18,event!E:F,2,0),"?",J18)) -> 自己抽卡 | G18: =IF(M18="","",SUBSTITUTE(VLOOKUP(M18,effect!B:E,4,0),"?",N18)) | H18: =SUBSTITUTE(VLOOKUP(O18,effect!B:E,4,0),"?",P18) -> 将自己抽到的卡公开 | I18: i_success_get_card | O18: Effect_i_public_card_i_get | Q18: 是 | R18: 被动 | S18: 必发 | U18: 连锁层 | X18: 独立 | Y18: 此次抽卡
A19: 64 | B19: 效果卡 | C19: 空遁·闪回 | F19: =IF(I19="","",SUBSTITUTE(VLOOKUP(I19,event!E:F,2,0),"?",J19)) -> 自己即将受到普攻 | G19: =IF(M19="","",SUBSTITUTE(VLOOKUP(M19,effect!B:E,4,0),"?",N19)) | H19: =SUBSTITUTE(VLOOKUP(O19,effect!B:E,4,0),"?",P19) -> 自己抽1卡且躲避此次普攻,自己可普攻 发动普攻者 1次 | I19: i_will_be_attacked | O19: compound_escape_to_sky_fight_back
A20: 65 | B20: 效果卡 | C20: 光斩·绝杀 | F20: =IF(I20="","",SUBSTITUTE(VLOOKUP(I20,event!E:F,2,0),"?",J20)) -> 自己即将受到致命伤血 | G20: =IF(M20="","",SUBSTITUTE(VLOOKUP(M20,effect!B:E,4,0),"?",N20)) | H20: =SUBSTITUTE(VLOOKUP(O20,effect!B:E,4,0),"?",P20) -> 此次伤血无效化且此回合自己攻击力翻倍，自己可对其进行1次普攻 | I20: i_will_be_fatal_dmg | O20: compound_lightning_blaze
A21: 66 | B21: 效果卡 | C21: 天华绝伦 | F21: =IF(I21="","",SUBSTITUTE(VLOOKUP(I21,event!E:F,2,0),"?",J21)) -> 此回合自己成功普攻超过2次且自己普攻成功 | G21: =IF(M21="","",SUBSTITUTE(VLOOKUP(M21,effect!B:E,4,0),"?",N21)) | H21: =SUBSTITUTE(VLOOKUP(O21,effect!B:E,4,0),"?",P21) -> 自己对 目标 造成4血超伤 | I21: i_success_attack_over_3_times | O21: Effect_i_attack_super | P21: 4
A22: 67 | B22: 效果卡 | C22: 神尚激光 | F22: =IF(I22="","",SUBSTITUTE(VLOOKUP(I22,event!E:F,2,0),"?",J22)) -> 己方回合自己未处于搏斗 | G22: =IF(M22="","",SUBSTITUTE(VLOOKUP(M22,effect!B:E,4,0),"?",N22)) | H22: =SUBSTITUTE(VLOOKUP(O22,effect!B:E,4,0),"?",P22) -> 此回合之后的3轮回内自己若受到致命伤血，使 发动者 受到之前自己丢光手卡数值×2的伤血 | I22: STATE_team_turn_i_positive | O22: compound_divine_laser
A23: 10670 | B23: 增益效果 | C23: 神尚激光1 | F23: =IF(I23="","",SUBSTITUTE(VLOOKUP(I23,event!E:F,2,0),"?",J23)) -> 自己受到致命伤血 | G23: =IF(M23="","",SUBSTITUTE(VLOOKUP(M23,effect!B:E,4,0),"?",N23)) | H23: =SUBSTITUTE(VLOOKUP(O23,effect!B:E,4,0),"?",P23) -> 自己使 目标 伤血 | I23: i_be_fatal_dmg | O23: Effect_i_let_enemy_effect_dmg
A24: 68 | B24: 效果卡 | C24: 轰炸星球 | F24: =IF(I24="","",SUBSTITUTE(VLOOKUP(I24,event!E:F,2,0),"?",J24)) -> 自己回合自己未处于搏斗 | G24: =IF(M24="","",SUBSTITUTE(VLOOKUP(M24,effect!B:E,4,0),"?",N24)) | H24: =SUBSTITUTE(VLOOKUP(O24,effect!B:E,4,0),"?",P24) -> 破坏场上所有场景卡和结界卡,每破坏1张,使 放置该卡者 伤2血 | I24: STATE_my_turn_positive | O24: Effect_SP_destory_planet
A25: 69 | B25: 效果卡 | C25: 最后的指望 | F25: =IF(I25="","",SUBSTITUTE(VLOOKUP(I25,event!E:F,2,0),"?",J25)) -> 自己即将死亡 | G25: =IF(M25="","",SUBSTITUTE(VLOOKUP(M25,effect!B:E,4,0),"?",N25)) | H25: =SUBSTITUTE(VLOOKUP(O25,effect!B:E,4,0),"?",P25) -> 自己指定1人,将 自己全部手卡 加入他手卡 | I25: i_will_die | O25: Effect_i_give_all_my_card_to_teammates
A26: 70 | B26: 效果卡 | C26: 双臂剑 | F26: =IF(I26="","",SUBSTITUTE(VLOOKUP(I26,event!E:F,2,0),"?",J26)) -> 自己回合自己未处于搏斗 | G26: =IF(M26="","",SUBSTITUTE(VLOOKUP(M26,effect!B:E,4,0),"?",N26)) -> 自己血-3 | H26: =SUBSTITUTE(VLOOKUP(O26,effect!B:E,4,0),"?",P26) -> 将卡堆最上方的2张武器卡给自己装备 | I26: STATE_my_turn_positive | M26: Effect_i_get_effect_dmg_by_myself | N26: 3 | O26: Effect_equip_weapon_from_deck | P26: 2
A27: 71 | B27: 效果卡 | C27: 离心续 | F27: =IF(I27="","",SUBSTITUTE(VLOOKUP(I27,event!E:F,2,0),"?",J27)) -> 自己普攻成功 | G27: =IF(M27="","",SUBSTITUTE(VLOOKUP(M27,effect!B:E,4,0),"?",N27)) | H27: =SUBSTITUTE(VLOOKUP(O27,effect!B:E,4,0),"?",P27) -> 自己对 被普攻者 进行1次普攻,此次普攻造成的普攻伤血翻倍 | I27: i_success_attack | O27: compound_centrifugal_combo
A28: 72 | B28: 效果卡 | C28: 混虚·太清 | F28: =IF(I28="","",SUBSTITUTE(VLOOKUP(I28,event!E:F,2,0),"?",J28)) -> 自己即将受到普攻 | G28: =IF(M28="","",SUBSTITUTE(VLOOKUP(M28,effect!B:E,4,0),"?",N28)) -> 自己丢光手卡 | H28: =SUBSTITUTE(VLOOKUP(O28,effect!B:E,4,0),"?",P28) -> 使 普攻者 血量减半,自己躲避本次普攻 | I28: i_will_be_attacked | M28: Effect_i_discard_card_all | O28: compound_chaos_bubble
A29: 73 | B29: 效果卡 | C29: 幻影剑 | F29: =IF(I29="","",SUBSTITUTE(VLOOKUP(I29,event!E:F,2,0),"?",J29)) -> 自己武器槽未满 | G29: =IF(M29="","",SUBSTITUTE(VLOOKUP(M29,effect!B:E,4,0),"?",N29)) | H29: =SUBSTITUTE(VLOOKUP(O29,effect!B:E,4,0),"?",P29) -> 装备上武器 | I29: STATE_i_weapon_not_full | O29: Effect_equip_weapon
A30: 74 | B30: 效果卡 | C30: 冷现·巨剑 | F30: =IF(I30="","",SUBSTITUTE(VLOOKUP(I30,event!E:F,2,0),"?",J30)) -> 自己受到伤血效果 | G30: =IF(M30="","",SUBSTITUTE(VLOOKUP(M30,effect!B:E,4,0),"?",N30)) -> 自己丢1手卡 | H30: =SUBSTITUTE(VLOOKUP(O30,effect!B:E,4,0),"?",P30) -> 自己指定1人伤2血 | I30: i_be_dmg_effect | M30: Effect_i_discard_card | N30: 1 | O30: Effect_i_point_one_enemy_get_effect_dmg | P30: 2
A31: 75 | B31: 效果卡 | C31: 隐天盾 | F31: =IF(I31="","",SUBSTITUTE(VLOOKUP(I31,event!E:F,2,0),"?",J31)) | G31: =IF(M31="","",SUBSTITUTE(VLOOKUP(M31,effect!B:E,4,0),"?",N31)) | H31: =SUBSTITUTE(VLOOKUP(O31,effect!B:E,4,0),"?",P31) -> 2轮回内,自己可丢1卡 无效化1次对己的非自主效果伤血 或 格挡1次普攻 | O31: compound_aetherveil_aegis
A32: 76 | B32: 效果卡 | C32: 破局·神击 | F32: =IF(I32="","",SUBSTITUTE(VLOOKUP(I32,event!E:F,2,0),"?",J32)) -> 自己普攻失败 | G32: =IF(M32="","",SUBSTITUTE(VLOOKUP(M32,effect!B:E,4,0),"?",N32)) | H32: =SUBSTITUTE(VLOOKUP(O32,effect!B:E,4,0),"?",P32) -> 自己可丢任意数量手卡，使 目标 受到丢卡数量的伤血且此次事件内无法行动.自己普攻 目标 1次, | I32: i_failed_attack | O32: Effect_SP_break_out_godattack
A33: 77 | B33: 效果卡 | C33: 旋地·回击 | F33: =IF(I33="","",SUBSTITUTE(VLOOKUP(I33,event!E:F,2,0),"?",J33)) -> 自己受到普攻 | G33: =IF(M33="","",SUBSTITUTE(VLOOKUP(M33,effect!B:E,4,0),"?",N33)) | H33: =SUBSTITUTE(VLOOKUP(O33,effect!B:E,4,0),"?",P33) -> 自己抽1卡,自己可普攻 发动普攻者 1次,本次普攻自己攻+1 | I33: i_be_attacked | O33: compound_circling_fight_back
A34: 30 | B34: 助攻卡 | C34: 决义·地割 | F34: =IF(I34="","",SUBSTITUTE(VLOOKUP(I34,event!E:F,2,0),"?",J34)) | G34: =IF(M34="","",SUBSTITUTE(VLOOKUP(M34,effect!B:E,4,0),"?",N34)) | H34: =SUBSTITUTE(VLOOKUP(O34,effect!B:E,4,0),"?",P34) -> 使 目标 伤1血，若命中则 目标 此事件内无法行动（目标可丢1卡躲避此效果） | O34: compound_earth_splitting
A35: 10300 | B35: 减益效果 | C35: 决义·地割1 | F35: =IF(I35="","",SUBSTITUTE(VLOOKUP(I35,event!E:F,2,0),"?",J35)) -> 自己受到伤血效果 | G35: =IF(M35="","",SUBSTITUTE(VLOOKUP(M35,effect!B:E,4,0),"?",N35)) | H35: =SUBSTITUTE(VLOOKUP(O35,effect!B:E,4,0),"?",P35) -> 给自己添加buff | I35: i_be_dmg_effect | O35: Effect_get_buff_myself | P35: =A36 -> 10301 | Q35: 是 | R35: 被动 | S35: 必发 | U35: 连锁层 | X35: 独立 | Y35: 此次效果伤血
A36: 10301 | B36: 减益效果 | C36: 决义·地割2 | F36: =IF(I36="","",SUBSTITUTE(VLOOKUP(I36,event!E:F,2,0),"?",J36)) | G36: =IF(M36="","",SUBSTITUTE(VLOOKUP(M36,effect!B:E,4,0),"?",N36)) | H36: =SUBSTITUTE(VLOOKUP(O36,effect!B:E,4,0),"?",P36) -> 自己无法行动 | O36: Buff_unmovable | Q36: 是 | R36: 被动 | X36: 独立 | Y36: 此次事件
A37: 31 | B37: 助攻卡 | C37: 劈夺斩 | F37: =IF(I37="","",SUBSTITUTE(VLOOKUP(I37,event!E:F,2,0),"?",J37)) | G37: =IF(M37="","",SUBSTITUTE(VLOOKUP(M37,effect!B:E,4,0),"?",N37)) | H37: =SUBSTITUTE(VLOOKUP(O37,effect!B:E,4,0),"?",P37) -> 此次普攻自己攻+1,自己查看 被攻者 所有手卡,并选1张加入自己手卡,若选中装备卡则直接给自己装备上 | O37: compound_plunder_cleave
A38: 10310 | B38: 增益效果 | C38: 劈夺斩1 | F38: =IF(I38="","",SUBSTITUTE(VLOOKUP(I38,event!E:F,2,0),"?",J38)) | G38: =IF(M38="","",SUBSTITUTE(VLOOKUP(M38,effect!B:E,4,0),"?",N38)) | H38: =SUBSTITUTE(VLOOKUP(O38,effect!B:E,4,0),"?",P38) -> 攻+1 | O38: Buff_extra_attack_power | P38: 1 | Q38: 是 | R38: 被动 | X38: 独立 | Y38: 此次普攻
A39: 32 | B39: 助攻卡 | C39: 剑飞·回斩 | F39: =IF(I39="","",SUBSTITUTE(VLOOKUP(I39,event!E:F,2,0),"?",J39)) -> 自己装备有武器 | G39: =IF(M39="","",SUBSTITUTE(VLOOKUP(M39,effect!B:E,4,0),"?",N39)) | H39: =SUBSTITUTE(VLOOKUP(O39,effect!B:E,4,0),"?",P39) -> 此次普攻自己装备的所有武器无效化,普攻结束后武器重新有效化且对手受到自己当前武器数量×2的伤血 | I39: STATE_i_have_weapon_equipped | O39: compound_weapon_out_and_back
A40: 10320 | B40: 增益效果 | C40: 剑飞·回斩1 | F40: =IF(I40="","",SUBSTITUTE(VLOOKUP(I40,event!E:F,2,0),"?",J40)) | G40: =IF(M40="","",SUBSTITUTE(VLOOKUP(M40,effect!B:E,4,0),"?",N40)) | H40: =SUBSTITUTE(VLOOKUP(O40,effect!B:E,4,0),"?",P40) -> 自己装备的所有武器无效化 | O40: Buff_my_weapon_all_invalid | Q40: 是 | R40: 被动 | X40: 独立 | Y40: 此次普攻
...

Sheet hide
A1: No | B1: description | C1: hide_effect_No | D1: hide_effect_description
A2: 60 | B2: =VLOOKUP(A2,general!$A:$C,3,) -> 神起·焰射 | C2: 407 | D2: =VLOOKUP(C2,general!$A:$C,3,) -> 蓝爆冰晶
A3: 61 | B3: =VLOOKUP(A3,general!$A:$C,3,) -> 近击·搏杀 | C3: 405 | D3: =VLOOKUP(C3,general!$A:$C,3,) -> 憎恨
A4: 62 | B4: =VLOOKUP(A4,general!$A:$C,3,) -> 阴势·突进 | C4: 401 | D4: =VLOOKUP(C4,general!$A:$C,3,) -> 闪
A5: 63 | B5: =VLOOKUP(A5,general!$A:$C,3,) -> 神空·闪降 | C5: 406 | D5: =VLOOKUP(C5,general!$A:$C,3,) -> 极天束
A6: 64 | B6: =VLOOKUP(A6,general!$A:$C,3,) -> 空遁·闪回 | C6: 400 | D6: =VLOOKUP(C6,general!$A:$C,3,) -> 连攻
A7: 65 | B7: =VLOOKUP(A7,general!$A:$C,3,) -> 光斩·绝杀 | C7: 400 | D7: =VLOOKUP(C7,general!$A:$C,3,) -> 连攻
A8: 66 | B8: =VLOOKUP(A8,general!$A:$C,3,) -> 天华绝伦 | C8: 403 | D8: =VLOOKUP(C8,general!$A:$C,3,) -> 暗枪
A9: 67 | B9: =VLOOKUP(A9,general!$A:$C,3,) -> 神尚激光 | C9: 400 | D9: =VLOOKUP(C9,general!$A:$C,3,) -> 连攻
A10: 68 | B10: =VLOOKUP(A10,general!$A:$C,3,) -> 轰炸星球 | C10: 402 | D10: =VLOOKUP(C10,general!$A:$C,3,) -> +4血
A11: 69 | B11: =VLOOKUP(A11,general!$A:$C,3,) -> 最后的指望 | C11: 400 | D11: =VLOOKUP(C11,general!$A:$C,3,) -> 连攻
A12: 70 | B12: =VLOOKUP(A12,general!$A:$C,3,) -> 双臂剑 | C12: 404 | D12: =VLOOKUP(C12,general!$A:$C,3,) -> 稻草人
A13: 71 | B13: =VLOOKUP(A13,general!$A:$C,3,) -> 离心续 | C13: 401 | D13: =VLOOKUP(C13,general!$A:$C,3,) -> 闪
... A40: 40 | B40: =VLOOKUP(A40,general!$A:$C,3,) -> 神·空·斩 | C40: 402 | D40: =VLOOKUP(C40,general!$A:$C,3,) -> +4血

Sheet rule
B1: 规则解释
B2: 超伤效果结算时无法被反制且无法触发任何被动
B3: 效果发动成功后才结算cost、效果，如果发动失败则不进行结算
B4: 普攻流程 | C4: a发动普攻攻击b
C5: a被动时点“我发动了普攻” | D5: b被动时点“我即将受到普攻”
C6: a主动时点“我发动了普攻” | D6: b主动时点“我即将受到普攻”
C7: 普攻伤害结算
C8: a被动时点“我普攻成功了” | D8: b被动时点“我受到了普攻”
C9: 分支1：b主动时点“我受到了普攻” | D9: a主动时点“我普攻成功了”
C10: 分支2：a主动时点“我普攻失败了” | D10: b主动时点“我成功避免普攻”
B11: 发动效果流程 | C11: a发动效果
C12: a被动时点“我发动效果” | D12: b被动时点“我即将受到效果”
C13: b主动时点"我即将受到效果" | D13: a主动时点“我发动了效果”
C14: 效果结算
C15: a被动时点“效果结算结果” | D15: b被动时点“效果结算结果”
C16: b主动时点“效果结算结果” | D16: a主动时点“效果结算结果”
B17: 每个时点，对于主动、选发效果，玩家只能发动一张卡
B18: 时点衍生：如果在某个时点玩家发动了某些效果后，原有时点流程改变，中间会增加该效果对应的时点，且如果这些效果结算后对应的结果不是“强制结束所有时点”，则继续原有时点流程，否则强制结束
B19: 每次发动一次新的普攻后，都会强制结束所有时点，相当于一次“康”，例如我发动一次效果伤血，他连锁一次普攻，则他普攻处理完后不会结算我发动的效果伤血，会强制结束事件，同理如果他普攻我一次而我此时连锁发动普攻他一次，则在我普攻他结算后强制结束事件，不会结算他进行的普攻
B20: 效果解释字样里的“目标”指的是连锁事件的对象
B21: “刷新x手卡”属于特殊效果：“丢x张卡，抽x张”，如果该效果结算时玩家因为某些效果免疫丢卡，则不会进行后续的抽卡，如果刷新x手卡数量大于该玩家手卡总数，则相当于丢光手卡再抽丢的数量的卡
B22: buff的？？？可分为此次事件、此次连锁层级、此次连锁层级单次契机 | C22: 此次事件指的是本次全部连锁结束前一切时间段
C23: 此次连锁层级指的是仅仅在此层效果处理时触发时会一直进行处理
C24: 此次连锁层级单次契机则在此层效果处理触发一次后或者此层连锁结束才消失
B25: 抽卡如果是x张，则是一次性获取x张，而不是一张张获取
B26: 玩家上限10张手卡，每个回合结束，必须将手卡限制在6张
B27: aoe效果会全员处理，但如果其中一个导致的后发连锁导致了事件被强制结束，则该次事件在全员处理完后才会被强制结束
A28: li | B28: 如果自己免疫一些cost效果，而cost为可变任意值，则默认为最大值（例如丢任意数量手卡则cost结果视为手卡数量最大值处理）
B29: 如果cost要求可以丢一定数量的卡但可以不丢，如果丢了数量少于该数量的卡则判断为cost失败（玩家本可选择不丢直接失败，但丢了少于要求数量的卡则视为玩家自己误操作承担后果）

Sheet weapon
A1: No | B1: name | C1: effect1 | D1: effect2 | E1: effect3 | F1: effect4 | G1: effect5 | H1: e1 | I1: e2 | J1: e3 | K1: e4 | L1: e5
A2: 0 | B2: =VLOOKUP(A2,general!$A:$C,3,) -> 承皇剑 | C2: 1001 | D2: 1002 | E2: 1003 | F2: 1004 | H2: =IF(C2="","",IFERROR(VLOOKUP(C2,general!A:C,3,0),"错误")) -> 承皇剑0 | I2: =IF(D2="","",IFERROR(VLOOKUP(D2,general!A:C,3,0),"错误")) -> 承皇剑1 | J2: =IF(E2="","",IFERROR(VLOOKUP(E2,general!A:C,3,0),"错误")) -> 承皇剑2 | K2: =IF(F2="","",IFERROR(VLOOKUP(F2,general!A:C,3,0),"错误")) -> 承皇剑3
A3: 1 | B3: =VLOOKUP(A3,general!$A:$C,3,) -> 疾风刃 | C3: 1011 | D3: 1012 | E3: 1013 | H3: =IFERROR(VLOOKUP(C3,general!A:C,3,0),"") -> 疾风刃0 | I3: =IFERROR(VLOOKUP(D3,general!A:C,3,0),"") -> 疾风刃1 | J3: =IF(E3="","",IFERROR(VLOOKUP(E3,general!A:C,3,0),"错误")) -> 疾风刃2 | K3: =IF(F3="","",IFERROR(VLOOKUP(F3,general!A:C,3,0),"错误"))
A4: 2 | B4: =VLOOKUP(A4,general!$A:$C,3,) -> 长者之镰 | C4: 1021 | D4: 1022 | E4: 1023 | H4: =IFERROR(VLOOKUP(C4,general!A:C,3,0),"") -> 长者之镰0 | I4: =IFERROR(VLOOKUP(D4,general!A:C,3,0),"") -> 长者之镰1 | J4: =IF(E4="","",IFERROR(VLOOKUP(E4,general!A:C,3,0),"错误")) -> 长者之镰2 | K4: =IF(F4="","",IFERROR(VLOOKUP(F4,general!A:C,3,0),"错误"))
A5: 3 | B5: =VLOOKUP(A5,general!$A:$C,3,) -> 噬剑之剑 | C5: 1031 | D5: 1032 | E5: 1033 | H5: =IFERROR(VLOOKUP(C5,general!A:C,3,0),"") -> 噬剑之剑0 | I5: =IFERROR(VLOOKUP(D5,general!A:C,3,0),"") -> 噬剑之剑1 | J5: =IF(E5="","",IFERROR(VLOOKUP(E5,general!A:C,3,0),"错误")) -> 噬剑之剑2 | K5: =IF(F5="","",IFERROR(VLOOKUP(F5,general!A:C,3,0),"错误"))
A6: 4 | B6: =VLOOKUP(A6,general!$A:$C,3,) -> 黑曜剑 | C6: 1043 | D6: 1044 | E6: 1045 | H6: =IFERROR(VLOOKUP(C6,general!A:C,3,0),"") -> 黑曜剑0 | I6: =IFERROR(VLOOKUP(D6,general!A:C,3,0),"") -> 黑曜剑1 | J6: =IF(E6="","",IFERROR(VLOOKUP(E6,general!A:C,3,0),"错误")) -> 黑曜剑2 | K6: =IF(F6="","",IFERROR(VLOOKUP(F6,general!A:C,3,0),"错误"))
A7: 5 | B7: =VLOOKUP(A7,general!$A:$C,3,) -> 食腐再生装置 | C7: 1051 | D7: 1052 | E7: 1053 | H7: =IFERROR(VLOOKUP(C7,general!A:C,3,0),"") -> 食腐再生装置1 | I7: =IFERROR(VLOOKUP(D7,general!A:C,3,0),"") -> 食腐再生装置2 | J7: =IF(E7="","",IFERROR(VLOOKUP(E7,general!A:C,3,0),"错误")) -> 食腐再生装置3 | K7: =IF(F7="","",IFERROR(VLOOKUP(F7,general!A:C,3,0),"错误"))
A8: 6 | B8: =VLOOKUP(A8,general!$A:$C,3,) -> 恩空法棒 | C8: 1061 | D8: 1062 | H8: =IFERROR(VLOOKUP(C8,general!A:C,3,0),"") -> 恩空法棒1 | I8: =IFERROR(VLOOKUP(D8,general!A:C,3,0),"") -> 恩空法棒2 | J8: =IF(E8="","",IFERROR(VLOOKUP(E8,general!A:C,3,0),"错误")) | K8: =IF(F8="","",IFERROR(VLOOKUP(F8,general!A:C,3,0),"错误"))
A9: 7 | B9: =VLOOKUP(A9,general!$A:$C,3,) -> 骷髅诡面 | C9: 1071 | D9: 1072 | E9: 1073 | F9: 1074 | H9: =IFERROR(VLOOKUP(C9,general!A:C,3,0),"") -> 骷髅诡面1 | I9: =IFERROR(VLOOKUP(D9,general!A:C,3,0),"") -> 骷髅诡面2 | J9: =IF(E9="","",IFERROR(VLOOKUP(E9,general!A:C,3,0),"错误")) -> 骷髅诡面3 | K9: =IF(F9="","",IFERROR(VLOOKUP(F9,general!A:C,3,0),"错误")) -> 骷髅诡面4
A10: 8 | B10: =VLOOKUP(A10,general!$A:$C,3,) -> 破败披风 | C10: 1081 | D10: 1082 | H10: =IFERROR(VLOOKUP(C10,general!A:C,3,0),"") -> 破败披风1 | I10: =IFERROR(VLOOKUP(D10,general!A:C,3,0),"") -> 破败披风2 | J10: =IF(E10="","",IFERROR(VLOOKUP(E10,general!A:C,3,0),"错误")) | K10: =IF(F10="","",IFERROR(VLOOKUP(F10,general!A:C,3,0),"错误"))
A11: 9 | B11: =VLOOKUP(A11,general!$A:$C,3,) -> 冠阳剜月斧 | C11: 1091 | D11: 1092 | E11: 1093 | H11: =IFERROR(VLOOKUP(C11,general!A:C,3,0),"") -> 冠阳剜月斧0 | I11: =IFERROR(VLOOKUP(D11,general!A:C,3,0),"") -> 冠阳剜月斧1 | J11: =IF(E11="","",IFERROR(VLOOKUP(E11,general!A:C,3,0),"错误")) -> 冠阳剜月斧2 | K11: =IF(F11="","",IFERROR(VLOOKUP(F11,general!A:C,3,0),"错误"))

Sheet buff
A1: No | B1: 中文说明 | C1: No | D1: 英文说明 | E1: 适用选项列 | F1: 解释
A2: 0 | B2: 被动 | C2: =A2 -> 0 | D2: negative
A3: 1 | B3: 主动 | C3: =A3 -> 1 | D3: positive
A4: 2000 | B4: 选发 | C4: =A4 -> 2000 | D4: trigger_optional
A5: 2001 | B5: 必发 | C5: =A5 -> 2001 | D5: trigger_mandatory
A7: 100000 | B7: 覆盖 | C7: =A7 -> 100000 | D7: Buff_type_reset
A8: 200000 | B8: 叠加 | C8: =A8 -> 200000 | D8: Buff_type_overlay
A9: 300000 | B9: 独立 | C9: =A9 -> 300000 | D9: Buff_type_independent
A11: 111 | B11: 是 | C11: =A11 -> 111
C12: =A12 -> 0
A13: 3001 | B13: 此次抽卡 | C13: =A13 -> 3001 | D13: this_time_get_card
A14: 3002 | B14: 此次效果伤血 | C14: =A14 -> 3002 | D14: this_time_effect_dmg
A15: 3004 | B15: 此次伤血 | C15: =A15 -> 3004 | D15: this_time_dmg
A16: 3005 | B16: 此次普攻 | C16: =A16 -> 3005 | D16: this_time_attack
A17: 3006 | B17: 此次效果结算 | C17: =A17 -> 3006 | D17: this_time_effect_launch
A18: 3010 | B18: 此次事件 | C18: =A18 -> 3010 | D18: this_event_launch
A19: 3030 | B19: 回合 | C19: =A19 -> 3030 | D19: duration_turn
A20: 3050 | B20: 轮回 | C20: =A20 -> 3050 | D20: duration_cycle
A21: 3100 | B21: 常驻 | C21: =A21 -> 3100 | D21: duration_permanent
A22: 3101 | B22: 自身效果常驻 | C22: =A22 -> 3101 | D22: duration_permanent_selfeffect | F22: 个人自身效果
A23: 3102 | B23: 武器常驻 | C23: =A23 -> 3102 | D23: duration_permanent_weaponeffect | F23: 个人武器技能效果

Sheet event
A1: No | B1: 场合 | C1: 状态 | D1: 时间点 | E1: condition_name | F1: description | G1: name | H1: 兼容1 | I1: 兼容2 | J1: 兼容3 | K1: 时间限制(谁的回合) | L1: 主体 | M1: 主被动 | N1: 时态（即将/当前） | O1: 具体要求
A2: -999 | E2: CHOICE_i_cancel_action | F2: 自己放弃行动 | G2: CHOICE_i_cancel_action
A3: -100 | E3: CHOICE_i_do_useless_choice | F3: 自己选择无效，重新选择 | G3: CHOICE_i_do_useless_choice
A4: 1000 | B4: 是 | E4: event_happen | F4: 事件发生 | G4: event_happen
A5: 10000 | C5: 是 | E5: Time_turn_end | F5: 回合结束 | G5: Time_turn_end
A6: 10100 | B6: 是 | E6: Time_attack_end | F6: 此次普攻结束 | G6: Time_attack_end
A7: 20000 | C7: 是 | E7: STATE_my_turn | F7: 自己回合 | G7: STATE_my_turn | K7: 自己回合 | L7: 自己 | M7: 主动 | N7: 当前 | O7: 未处于搏斗
A8: 20001 | C8: 是 | E8: STATE_my_turn_enough_weapon_token | F8: 自己回合且此武器token数量大于? | G8: STATE_my_turn_enough_token
A9: 20010 | C9: 是 | E9: STATE_my_turn_positive | F9: 自己回合自己未处于搏斗 | G9: STATE_my_turn_positive | K9: 自己回合 | L9: 自己 | M9: 主动 | N9: 当前 | O9: 未处于搏斗且自己武器槽未满
A10: 20020 | C10: 是 | E10: STATE_my_turn_positive_weapon_not_full | F10: 自己回合自己未处于搏斗且自己武器槽未满 | G10: STATE_my_turn_positive_weapon_not_full | K10: 自己回合 | L10: 自己 | M10: 主动 | N10: 当前 | O10: 未处于搏斗
A11: 20200 | C11: 是 | E11: STATE_team_turn_i_positive | F11: 己方回合自己未处于搏斗 | G11: STATE_team_turn_i_positive | K11: 己方回合 | L11: 自己 | M11: 主动 | N11: 当前 | O11: 未处于搏斗
A12: 20300 | C12: 是 | E12: STATE_i_weapon_not_full | F12: 自己武器槽未满 | G12: STATE_i_weapon_not_full | L12: 自己 | N12: 当前 | O12: 武器槽未满
A13: 20310 | C13: 是 | E13: STATE_i_have_weapon_equipped | F13: 自己装备有武器 | G13: STATE_i_have_weapon_equipped
A14: 20320 | C14: 是 | E14: STATE_i_involve_event_over_4_chains | F14: 自己参与的1次事件连锁超过4次 | G14: STATE_i_involve_event_over_4_chains
B15: 是 | E15: someone_will_get_card | F15: 有人即将抽卡 | G15: someone_will_get_card
E16: someone_launch_effect | F16: 有人发动效果 | G16: someone_launch_effect
A17: 30100 | B17: 是 | E17: someone_dead | F17: 有人死亡时 | G17: someone_dead
A18: 30100 | B18: 是 | E18: someone_dead_not_me | F18: 除己外有人死亡时 | G18: someone_dead_not_me
A19: 40100 | B19: 是 | E19: other_use_card | F19: 除己外有人使用手卡 | G19: other_use_card
A20: 40200 | B20: 是 | E20: other_dead | F20: 除己外有人死亡 | G20: other_dead
A21: 90002 | B21: 是 | E21: Result_force_end_event | F21: 强制结束事件 | G21: Result_force_end_event
A22: 90003 | B22: 是 | E22: Result_force_end_turn | F22: 强制结束回合 | G22: Result_force_end_turn
A23: 100000 | B23: 是 | E23: i_used_card | F23: 自己发动手卡 | G23: i_used_card
A24: 110100 | B24: 是 | E24: i_success_use_card | F24: 自己成功发动手卡 | G24: i_success_use_card
A25: 110101 | B25: 是 | C25: 是 | E25: i_success_use_card_in_my_turn | F25: 自己回合自己成功发动手卡 | G25: i_success_use_card_in_my_turn
A26: 110200 | B26: 是 | E26: i_success_get_one_card | F26: 自己每抽1卡 | G26: i_success_get_one_card | H26: i_success_get_card
A27: 110300 | B27: 是 | E27: i_success_get_card | F27: 自己抽卡 | G27: i_success_get_card
A28: 110400 | B28: 是 | E28: i_success_do_fight | F28: 自己参与搏斗 | G28: i_success_do_fight
A29: 110500 | B29: 是 | E29: i_success_do_dmg | F29: 自己成功造成伤血 | G29: i_success_do_dmg
A30: 110501 | B30: 是 | E30: i_success_do_dmg_effect | F30: 自己成功造成效果伤血 | G30: i_success_do_dmg_effect
A31: 110600 | B31: 是 | E31: i_success_attack | F31: 自己普攻成功 | G31: i_success_attack
A32: 110610 | B32: 可以 | C32: 可以 | E32: i_success_attack_or_my_turn_positive | F32: 自己普攻成功或自己回合自己未处于搏斗状态 | G32: i_success_attack_or_my_turn_positive | H32: i_success_attack
A33: 110620 | B33: 是 | C33: 是 | E33: i_success_attack_over_3_times | F33: 此回合自己成功普攻超过2次且自己普攻成功 | G33: i_success_attack_over_3_times | H33: i_success_attack
A34: 120100 | B34: 是 | E34: i_failed_launch_effect | F34: 自己效果发动失败 | G34: i_failed_launch_effect
A35: 120200 | B35: 是 | E35: i_failed_do_dmg | F35: 自己未能成功造成伤害 | G35: i_failed_do_dmg | H35: i_failed_do_dmg_effect | I35: i_failed_attack
A36: 120201 | B36: 是 | E36: i_failed_do_dmg_effect | F36: 自己未能成功造成效果伤血 | G36: i_failed_do_dmg_effect
A37: 120300 | B37: 是 | E37: i_failed_attack | F37: 自己普攻失败 | G37: i_failed_attack | H37: i_failed_attack_be_defend | I37: i_failed_attack_be_escape
A38: 120301 | B38: 是 | E38: i_failed_attack_be_defend | F38: 自己普攻被格挡 | G38: i_failed_attack_be_defend
A39: 120302 | B39: 是 | E39: i_failed_attack_be_escape | F39: 自己普攻被躲避 | G39: i_failed_attack_be_escape
A40: 130000 | B40: 是 | E40: i_will_attack | F40: 自己发动普攻 | G40: i_will_attack
...

Sheet effect
A1: No | B1: name | C1: type | D1: 简称 | E1: description | F1: 备注 | G1: 效果1 | H1: value1 | I1: 效果2 | J1: value2 | K1: 效果3 | L1: value3 | M1: 效果4 | N1: value4
A2: 901000 | B2: Effect_get_buff_one_enemy | C2: 元效果 | E2: 给单一对手添加buff | F2: 需要添加general表内具体buff编号，本表内buff仅为效果意义
A3: 901001 | B3: Effect_get_buff_one_enemy_50percent | C3: 元效果 | E3: 给单一对手添加buff(50概率)
A4: 901005 | B4: Effect_get_buff_myself | C4: 元效果 | E4: 给自己添加buff | F4: 需要添加general表内具体buff编号，本表内buff仅为效果意义
A5: 901010 | B5: Effect_refresh_card_all | C5: 元效果 | E5: 所有人随机刷新?手卡
A6: 901020 | B6: Effect_i_point_one_enemy_get_effect_dmg | C6: 元效果 | E6: 自己指定1人伤?血
A7: 901030 | B7: Effect_i_point_one_get_heal | C7: 元效果 | E7: 自己指定1人回复?血
A8: 901040 | B8: Effect_i_point_one_enemy_get_effect_dmg_50percent | C8: 元效果 | E8: 自己指定1人50%伤?血
A9: 901050 | B9: Effect_i_give_all_my_card_to_teammates | C9: 元效果 | E9: 自己指定1人,将 自己全部手卡 加入他手卡
A10: 901070 | B10: Effect_i_recover_to_limit | C10: 元效果 | E10: 自己血量回满
A11: 901080 | B11: Effect_hatred | C11: 元效果 | D11: 憎恨 | E11: 自己选一以下效果进行发动： (1)指定1人的人物效果一轮回内无法发动 (2)破坏场上一张 装备卡 或 场景卡 或 结界卡 (3)非人物卡 发动无效并破坏
A12: 901090 | B12: Effect_i_recover | C12: 元效果 | E12: 自己回复?血
A13: 901100 | B13: Effect_SP_i_defend_attack_throne_succeed_sword | C13: 元效果 | D13: 承皇剑2 | E13: 自己格挡此次普攻，格挡第4次普攻后将此装备卡破坏
A14: 901110 | B14: Effect_i_defend_attack | C14: 元效果 | E14: 自己格挡此次普攻
A15: 901120 | B15: Effect_i_claim_attack | C15: 元效果 | E15: 自己发动1次普攻 | F15: 任意对象
A16: 901130 | B16: Effect_i_attack_enemy | C16: 元效果 | E16: 自己普攻 目标 1次 | F16: 唯一对象，事件连锁者
A17: 901140 | B17: Effect_i_attack_super | C17: 元效果 | E17: 自己对 目标 造成?血超伤
A18: 901150 | B18: Effect_SP_burst_fight | C18: 元效果 | D18: 近击搏杀 | E18: 自己对 目标 造成?血超伤，此回合被强制结束
A19: 901160 | B19: Effect_i_get_card | C19: 元效果 | E19: 自己抽?卡
A20: 901170 | B20: Effect_i_escape_attack_and_can_fight_back | C20: 元效果 | D20: 空遁闪回 | E20: 自己躲避此次普攻,自己可普攻 目标 1次
A21: 901180 | B21: Effect_i_can_attack_back_with_enforce | C21: 元效果 | D21: 旋地·回击 | E21: 自己可普攻 目标 1次,本次普攻自己攻+?
A22: 901190 | B22: Effect_i_point_enemy_get_effect_dmg_escape_available | C22: 元效果 | E22: 自己指定1敌人伤?血（目标可丢1卡躲避此效果）
A23: 901195 | B23: Effect_i_let_enemy_get_effect_dmg_escape_available | C23: 元效果 | E23: 自己使 目标 伤?血（目标可丢1卡躲避此效果）
A24: 901200 | B24: Effect_i_immune_effect_dmg | C24: 元效果 | E24: 自己不受此次伤血影响
A25: 901210 | B25: Effect_equip_weapon | C25: 元效果 | E25: 装备上武器
A26: 901230 | B26: Effect_deck_top_card_to_graveyard | C26: 元效果 | E26: 卡堆最上方?张卡送入废卡区
A27: 901240 | B27: Effect_destroy_enemy_weapon_random | C27: 元效果 | E27: 随机破坏 与自己搏斗者 装备的1张装备卡
A28: 901250 | B28: Effect_i_let_enemy_effect_dmg | C28: 元效果 | E28: 自己使 目标 伤?血
A29: 901260 | B29: Effect_i_let_enemy_blood_halve | C29: 元效果 | E29: 使 目标 血量减半
A30: 901270 | B30: Effect_i_escape_attack | C30: 元效果 | D30: 闪 | E30: 自己躲避本次普攻
A31: 901280 | B31: Effect_SP_break_out_godattack | C31: 元效果 | E31: 自己可丢任意数量手卡，使 目标 受到丢卡数量的伤血且此次事件内无法行动.自己普攻 目标 1次,
A32: 901290 | B32: Effect_SP_destory_planet | C32: 元效果 | E32: 破坏场上所有场景卡和结界卡,每破坏1张,使 放置该卡者 伤2血
A33: 901300 | B33: Effect_equip_weapon_from_deck | C33: 元效果 | E33: 将卡堆最上方的?张武器卡给自己装备
A34: 901310 | B34: Effect_token_this_card_add | C34: 元效果 | E34: 给此卡放置1指示物
A35: 901330 | B35: Effect_SP_scarecrow | C35: 元效果 | D35: 稻草人 | E35: 躲避此次普攻，目标 武器全被破坏
A36: 901340 | B36: Effect_i_let_enemy_effect_dmg_my_weapon_quantity | C36: 元效果 | E36: 目标 受到自己当前武器数量×2的伤血
A37: 901350 | B37: Effect_SP_fire_splash | C37: 元效果 | E37: 敌方所有人武器全部破坏且伤?血
A38: 901360 | B38: Effect_SP_divine_laser_effect | C38: 元效果 | E38: 自己丢光手卡，统计丢卡总数，并添加专属buff
A39: 901380 | B39: Effect_i_let_enemy_refresh_card_randomly | C39: 元效果 | E39: 自己使 目标 随机刷新?卡
A40: 901390 | B40: Effect_i_let_enemy_random_discard_card | C40: 元效果 | E40: 自己使 目标 随机丢?卡
...
